2021-05-18 09:05:20,919 INFO    MainThread:67851 [wandb_setup.py:_flush():69] setting env: {}
2021-05-18 09:05:20,920 INFO    MainThread:67851 [wandb_setup.py:_flush():69] setting login settings: {}
2021-05-18 09:05:20,920 INFO    MainThread:67851 [wandb_init.py:_log_setup():336] Logging user logs to /home/indika/Programming/Projects/Python/Artifical-Intelligence/PyTorch/CNN/American-Sign-Language-Recognition/wandb/run-20210518_090520-it630znc/logs/debug.log
2021-05-18 09:05:20,920 INFO    MainThread:67851 [wandb_init.py:_log_setup():337] Logging internal logs to /home/indika/Programming/Projects/Python/Artifical-Intelligence/PyTorch/CNN/American-Sign-Language-Recognition/wandb/run-20210518_090520-it630znc/logs/debug-internal.log
2021-05-18 09:05:20,920 INFO    MainThread:67851 [wandb_init.py:_jupyter_setup():287] configuring jupyter hooks <wandb.sdk.wandb_init._WandbInit object at 0x7feee6a23748>
2021-05-18 09:05:20,921 INFO    MainThread:67851 [wandb_init.py:init():369] calling init triggers
2021-05-18 09:05:20,921 INFO    MainThread:67851 [wandb_init.py:init():376] wandb.init called with sweep_config: {}
config: {}
2021-05-18 09:05:20,921 INFO    MainThread:67851 [wandb_init.py:init():418] starting backend
2021-05-18 09:05:20,921 INFO    MainThread:67851 [backend.py:_multiprocessing_setup():72] multiprocessing start_methods=fork,spawn,forkserver, using: spawn
2021-05-18 09:05:20,961 INFO    MainThread:67851 [backend.py:ensure_launched():132] starting backend process...
2021-05-18 09:05:20,993 INFO    MainThread:67851 [backend.py:ensure_launched():137] started backend process with pid: 68453
2021-05-18 09:05:20,994 INFO    MainThread:67851 [wandb_init.py:init():423] backend started and connected
2021-05-18 09:05:21,005 INFO    MainThread:67851 [wandb_init.py:init():465] updated telemetry
2021-05-18 09:05:21,006 INFO    MainThread:67851 [wandb_init.py:init():484] communicating current version
2021-05-18 09:05:26,007 INFO    MainThread:67851 [wandb_init.py:init():497] communicating run to backend with 30 second timeout
2021-05-18 09:05:49,201 ERROR   Thread-4  :67851 [retry.py:__call__():126] Retry attempt failed:
Traceback (most recent call last):
  File "/home/indika/anaconda3/lib/python3.7/site-packages/urllib3/connection.py", line 159, in _new_conn
    (self._dns_host, self.port), self.timeout, **extra_kw)
  File "/home/indika/anaconda3/lib/python3.7/site-packages/urllib3/util/connection.py", line 57, in create_connection
    for res in socket.getaddrinfo(host, port, family, socket.SOCK_STREAM):
  File "/home/indika/anaconda3/lib/python3.7/socket.py", line 748, in getaddrinfo
    for res in _socket.getaddrinfo(host, port, family, type, proto, flags):
socket.gaierror: [Errno -3] Temporary failure in name resolution

During handling of the above exception, another exception occurred:

Traceback (most recent call last):
  File "/home/indika/anaconda3/lib/python3.7/site-packages/urllib3/connectionpool.py", line 600, in urlopen
    chunked=chunked)
  File "/home/indika/anaconda3/lib/python3.7/site-packages/urllib3/connectionpool.py", line 343, in _make_request
    self._validate_conn(conn)
  File "/home/indika/anaconda3/lib/python3.7/site-packages/urllib3/connectionpool.py", line 839, in _validate_conn
    conn.connect()
  File "/home/indika/anaconda3/lib/python3.7/site-packages/urllib3/connection.py", line 301, in connect
    conn = self._new_conn()
  File "/home/indika/anaconda3/lib/python3.7/site-packages/urllib3/connection.py", line 168, in _new_conn
    self, "Failed to establish a new connection: %s" % e)
urllib3.exceptions.NewConnectionError: <urllib3.connection.VerifiedHTTPSConnection object at 0x7feee669f550>: Failed to establish a new connection: [Errno -3] Temporary failure in name resolution

During handling of the above exception, another exception occurred:

Traceback (most recent call last):
  File "/home/indika/anaconda3/lib/python3.7/site-packages/requests/adapters.py", line 449, in send
    timeout=timeout
  File "/home/indika/anaconda3/lib/python3.7/site-packages/urllib3/connectionpool.py", line 638, in urlopen
    _stacktrace=sys.exc_info()[2])
  File "/home/indika/anaconda3/lib/python3.7/site-packages/urllib3/util/retry.py", line 398, in increment
    raise MaxRetryError(_pool, url, error or ResponseError(cause))
urllib3.exceptions.MaxRetryError: HTTPSConnectionPool(host='api.wandb.ai', port=443): Max retries exceeded with url: /graphql (Caused by NewConnectionError('<urllib3.connection.VerifiedHTTPSConnection object at 0x7feee669f550>: Failed to establish a new connection: [Errno -3] Temporary failure in name resolution'))

During handling of the above exception, another exception occurred:

Traceback (most recent call last):
  File "/home/indika/anaconda3/lib/python3.7/site-packages/wandb/sdk/lib/retry.py", line 102, in __call__
    result = self._call_fn(*args, **kwargs)
  File "/home/indika/anaconda3/lib/python3.7/site-packages/wandb/sdk/internal/internal_api.py", line 127, in execute
    return self.client.execute(*args, **kwargs)
  File "/home/indika/anaconda3/lib/python3.7/site-packages/wandb/vendor/gql-0.2.0/gql/client.py", line 52, in execute
    result = self._get_result(document, *args, **kwargs)
  File "/home/indika/anaconda3/lib/python3.7/site-packages/wandb/vendor/gql-0.2.0/gql/client.py", line 60, in _get_result
    return self.transport.execute(document, *args, **kwargs)
  File "/home/indika/anaconda3/lib/python3.7/site-packages/wandb/vendor/gql-0.2.0/gql/transport/requests.py", line 38, in execute
    request = requests.post(self.url, **post_args)
  File "/home/indika/anaconda3/lib/python3.7/site-packages/requests/api.py", line 116, in post
    return request('post', url, data=data, json=json, **kwargs)
  File "/home/indika/anaconda3/lib/python3.7/site-packages/requests/api.py", line 60, in request
    return session.request(method=method, url=url, **kwargs)
  File "/home/indika/anaconda3/lib/python3.7/site-packages/requests/sessions.py", line 533, in request
    resp = self.send(prep, **send_kwargs)
  File "/home/indika/anaconda3/lib/python3.7/site-packages/requests/sessions.py", line 646, in send
    r = adapter.send(request, **kwargs)
  File "/home/indika/anaconda3/lib/python3.7/site-packages/requests/adapters.py", line 516, in send
    raise ConnectionError(e, request=request)
requests.exceptions.ConnectionError: HTTPSConnectionPool(host='api.wandb.ai', port=443): Max retries exceeded with url: /graphql (Caused by NewConnectionError('<urllib3.connection.VerifiedHTTPSConnection object at 0x7feee669f550>: Failed to establish a new connection: [Errno -3] Temporary failure in name resolution'))
2021-05-18 09:05:56,007 INFO    MainThread:67851 [interface.py:_communicate_run():649] couldn't get run from backend
2021-05-18 09:05:56,008 ERROR   MainThread:67851 [wandb_init.py:init():501] backend process timed out
2021-05-18 09:05:56,008 ERROR   MainThread:67851 [wandb_init.py:init():510] encountered error: Error communicating with wandb process
try: wandb.init(settings=wandb.Settings(start_method='fork'))
or:  wandb.init(settings=wandb.Settings(start_method='thread'))
For more info see: https://docs.wandb.ai/library/init#init-start-error
